Workbook

Sheet Overview
B2: Club Overview Information | H2: Chart Data
B3: Name | C3: The Liverpool Football Club and Athletic Grounds Limited | H3: Data Point | I3: 2015 | J3: 2016 | K3: 2017 | L3: 2018 | M3: 2019 | N3: 2020 | O3: 2021 | P3: 2022 | Q3: 2023 | R3: 2024
B4: Company Overview | C4: AI Description of Liverpool FC. | H4: Revenue | I4: ='Income Statement'!C7 -> 298 | J4: ='Income Statement'!D7 -> 301.7 | K4: ='Income Statement'!E7 -> 364.5 | L4: ='Income Statement'!F7 -> 455.1 | M4: ='Income Statement'!G7 -> 533 | N4: ='Income Statement'!H7 -> 489.9 | O4: ='Income Statement'!I7 -> 487.3 | P4: ='Income Statement'!J7 -> 594.3 | ... R4: ='Income Statement'!L7 -> 613.8
B5: Website | C5: www.liverpoolfc.com | H5: Revenue % Chg | I5: =(I4-I4)/$I$4 -> 0 | J5: =(J4-$I$4)/$I$4 -> 0.012416107 | K5: =(K4-$I$4)/$I$4 -> 0.22315436 | L5: =(L4-$I$4)/$I$4 -> 0.52718121 | M5: =(M4-$I$4)/$I$4 -> 0.7885906 | N5: =(N4-$I$4)/$I$4 -> 0.64395973 | O5: =(O4-$I$4)/$I$4 -> 0.6352349 | P5: =(P4-$I$4)/$I$4 -> 0.9942953 | Q5: =(Q4-$I$4)/$I$4 -> 0.99295302 | R5: =(R4-$I$4)/$I$4 -> 1.0597315
B6: Country | C6: UK | H6: EBITDA | I6: ='Income Statement'!C14 -> 73 | J6: ='Income Statement'!D14 -> 35.2 | K6: ='Income Statement'!E14 -> 73.5 | L6: ='Income Statement'!F14 -> 94.7 | M6: ='Income Statement'!G14 -> 123.4 | N6: ='Income Statement'!H14 -> 41.7 | O6: ='Income Statement'!I14 -> 77.1 | P6: ='Income Statement'!J14 -> 96.4 | ... R6: ='Income Statement'!L14 -> 60.6
B7: League | C7: Premier League | H7: EBITDA % Chg | I7: =(I6-I6)/$I$6 -> 0 | J7: =(J6-$I$6)/$I$6 -> -0.51780822 | K7: =(K6-$I$6)/$I$6 -> 0.0068493151 | L7: =(L6-$I$6)/$I$6 -> 0.29726027 | M7: =(M6-$I$6)/$I$6 -> 0.69041096 | N7: =(N6-$I$6)/$I$6 -> -0.42876712 | O7: =(O6-$I$6)/$I$6 -> 0.056164384 | P7: =(P6-$I$6)/$I$6 -> 0.32054795 | Q7: =(Q6-$I$6)/$I$6 -> 0.14794521 | R7: =(R6-$I$6)/$I$6 -> -0.16986301
B8: Year Founded | C8: 1892 | H8: Valuation | I8: ='Valuation Calcs'!M32 -> 1884.625 | J8: ='Valuation Calcs'!M31 -> 1705.65 | K8: ='Valuation Calcs'!M30 -> 2116.1875 | L8: ='Valuation Calcs'!M29 -> 2547.9375 | M8: ='Valuation Calcs'!M28 -> 2972.075 | N8: ='Valuation Calcs'!M27 -> 2161.7625 | O8: ='Valuation Calcs'!M26 -> 2983.4375 | P8: ='Valuation Calcs'!M25 -> 3397.9 | Q8: ='Valuation Calcs'!M24 -> 3498.125 | R8: ='Valuation Calcs'!M23 -> 3317.5523
B9: Location: | C9: Liverpool
B10: Owner(s) | C10: Fenway Sports Group | H10: Liverpool FC - Historical Revenue
B11: Owner Location | C11: USA
B12: CEO | C12: Billy Hogan
B13: Chairman | C13: Tom Werner
B15: Profile
B16: Revenue (£M) | C16: ='Income Statement'!L7 -> 613.8
B17: Employees | C17: =Management!M12 -> 1011
B18: Valuation (£M) | C18: =R8 -> 3317.5523
B19: EBITDA | C19: ='Income Statement'!L14 -> 60.6
B21: Margins
B22: Gross | C22: ='Income Statement'!L9/'Income Statement'!L7 -> 0.86412512
B23: EBITDA | C23: ='Income Statement'!L14/'Income Statement'!L7 -> 0.098729228
B24: Operating | C24: ='Income Statement'!L25/'Income Statement'!L7 -> -0.07754969
B25: Pre-Tax | C25: ='Income Statement'!L29/'Income Statement'!L7 -> -0.092864125
B26: Net | C26: ='Income Statement'!L31/'Income Statement'!L7 -> -0.070707071
B27: FCF | C27: =('Cash Flow Statement V1'!L17-'Cash Flow Statement V1'!L23)/'Income Statement'!L7 -> 0.21407625
B28: FCF After Player Trading | C28: =('Cash Flow Statement V1'!L17+'Cash Flow Statement V1'!L24)/'Income Statement'!L7 -> -0.18426197
B30: Growth
B31: Rev 3Yr | C31: =('Income Statement'!L7-'Income Statement'!J7)/('Income Statement'!J7) -> 0.032811711
B32: Rev 5Yr | C32: =('Income Statement'!L7-'Income Statement'!H7)/('Income Statement'!H7) -> 0.25290876
B33: Rev 10Yr | C33: =('Income Statement'!L7-'Income Statement'!C7)/('Income Statement'!C7) -> 1.0597315
B34: EBITDA 3Yr | C34: =('Income Statement'!L14-'Income Statement'!J14)/('Income Statement'!J14) -> -0.37136929
B35: EBITDA 5Yr | C35: =('Income Statement'!L14-'Income Statement'!H14)/('Income Statement'!H14) -> 0.45323741
B36: EBITDA 10Yr | C36: =('Income Statement'!L14-'Income Statement'!C14)/('Income Statement'!C14) -> -0.16986301
B38: Financial Health
B39: Cash | C39: ='Balance Sheet'!L14 -> 7.5
B40: Net Debt | C40: ='Balance Sheet'!L15 -> 306.8
B41: Football Net Debt (FND) | C41: ='Balance Sheet'!L23 -> 376.7
B42: FND Less Owner Debt | C42: ='Balance Sheet'!L24 -> 178
B44: Key Ratios
B45: Wage-to-Revenue | C45: ='Income Statement'!L35 -> 0.62903226
B46: Wages + Amortization to Revenue | C46: ='Income Statement'!L37 -> 0.81557511
...

Sheet Ownership
B2: Ownership
B3: Share Ownership Summary Table
B4: Ultimate Investor | C4: % of Fenway Sports Group LLC | D4: Direct % of FSG Football Group | E4: Total Effective % of FSG Football Group | I4: Ownership Arrangement Diagram
B5: John Henry | C5: 0.4 | D5: - | E5: =C5*0.97 -> 0.388
B6: Mike Gordon | C6: 0.12 | D6: - | E6: =C6*0.97 -> 0.1164
B7: Tom Werner | C7: 0.1 | D7: - | E7: =C7*0.97 -> 0.097
B8: RedBird Capital Partners (via Rouge Aggregator LP) | C8: 0.11 | D8: - | E8: =C8*0.97 -> 0.1067
B9: Arctos | C9: 0.05 | E9: =C9*0.97 -> 0.0485
B10: Lebron James & Maverick Carter | C10: 0.01 | E10: =C10*0.97 -> 0.0097
B11: ~20-25 other investors (each < 10%) | C11: 0.21 | D11: - | E11: =C11*0.97 -> 0.2037
B12: Dynasty Equity Investmnet Vehicle | C12: - | D12: 0.03 | E12: =D12*1 -> 0.03
B14: MCO Links
B15: Other Sporting Asset | C15: Country / League | D15: Stake | E15: Date Bought | F15: Current Valuation ($B) | G15: Stake Valuation ($B)
B16: Boston Red Sox | C16: USA / MLB | D16: 1 | E16: 2002 | F16: 4.8 | G16: =F16*D16 -> 4.8
B17: Pittsburgh Penguins | C17: USA / NHL | D17: 1 | E17: 2021 | F17: 0.99 | G17: =F17*D17 -> 0.99
B18: RFK Racing | C18: USA / NASCAR | D18: 0.5 | E18: 2007 | F18: Private (50% JV) | G18: -
B19: PGA Tour Enterprises | C19: Glboal / Golf | D19: 0.15 | E19: 2021 | F19: 10 | G19: =F19*D19 -> 1.5
B20: Boston Common Golf | C20: USA / TGL Golf League | D20: 1 | E20: 2024 | F20: N/A | G20: -
B21: New England Sports Network | C21: USA / Regional Sports Network | D21: 0.8 | E21: 1984 | F21: N/A | G21: -

Sheet Management
B2: Management | P2: Executive Team
B3: Liverpool FC | C3: 2014 | D3: 2015 | E3: 2016 | F3: 2017 | G3: 2018 | H3: 2019 | I3: 2020 | J3: 2021 | K3: 2022 | L3: 2023 | M3: 2024 | P3: Principal Owner | Q3: John Henry
B4: Directors | P4: Chairman | Q4: Tom Werner
B5: Directors Remuneration (£k) | C5: 1051 | D5: 1384 | E5: 1704 | F5: 1649 | G5: 2276 | H5: 2876 | I5: 2167 | J5: 3140 | K5: 3365 | L5: 4193 | M5: 3864 | P5: Chief Executve Officer | Q5: Billy Hogan
B6: Highest Paid Director (£k) | C6: 1032 | D6: 1199 | E6: 1215 | F6: 914 | G6: 1329 | H6: 1764 | I6: 1306 | J6: 1664 | K6: 2063 | L6: 2244 | M6: 2164 | P6: Club Secretary | Q6: Danny Stanway
P7: Manager (Coaching Staff) | Q7: Arne Slot
B8: Staff | P8: Managing Director | Q8: Andy Hughes
B9: Playing Staff | C9: 138 | D9: 145 | E9: 139 | F9: 152 | G9: 178 | H9: 178 | I9: 203 | J9: 218 | K9: 225 | L9: 238 | M9: 229 | P9: Sporting Director | Q9: Richard Hughes
B10: Ground & Maintenance | C10: 51 | D10: 53 | E10: 61 | F10: 65 | G10: 66 | H10: 65 | I10: 57 | J10: 60 | K10: 67 | L10: 69 | M10: 69
B11: Administration, Commercial & Other | C11: 378 | D11: 438 | E11: 500 | F11: 518 | G11: 593 | H11: 610 | I11: 620 | J11: 686 | K11: 713 | L11: 701 | M11: 713 | P11: Director | Q11: Mr M. Gordon
B12: Total Full Time Staff | C12: =SUM(C9:C11) -> 567 | D12: =SUM(D9:D11) -> 636 | E12: =SUM(E9:E11) -> 700 | F12: =SUM(F9:F11) -> 735 | G12: =SUM(G9:G11) -> 837 | H12: =SUM(H9:H11) -> 853 | I12: =SUM(I9:I11) -> 880 | J12: =SUM(J9:J11) -> 964 | ... M12: =SUM(M9:M11) -> 1011 | P12: Director | Q12: Mr M. Egan
P13: Director | Q13: Sir K. Dalglish
B14: Match Day Part Time | C14: 1264 | D14: 1368 | E14: 1496 | F14: 1716 | G14: 1965 | H14: 2073 | I14: 1955 | J14: 945 | K14: 1930 | L14: 2062 | M14: 2109
B15: Part Time Scouts & Staff | C15: 81 | D15: 67 | E15: 27 | F15: 10 | G15: 32 | H15: 36 | I15: 0 | J15: 0 | K15: 0 | L15: 0 | M15: 0
B16: Total Staff | C16: =C12+C14+C15 -> 1912 | D16: =D12+D14+D15 -> 2071 | E16: =E12+E14+E15 -> 2223 | F16: =F12+F14+F15 -> 2461 | G16: =G12+G14+G15 -> 2834 | H16: =H12+H14+H15 -> 2962 | I16: =I12+I14+I15 -> 2835 | J16: =J12+J14+J15 -> 1909 | ... M16: =M12+M14+M15 -> 3120
B18: £000
B19: Wages and Salaries | C19: 127182 | D19: 145654 | E19: 184829 | F19: 184300 | G19: 232672 | H19: 276197 | I19: 289341 | J19: 277808 | K19: 323527 | L19: 329980 | M19: 341354
B20: Social Secruity Costs | C20: 15937 | D20: 18299 | E20: 22625 | F20: 22407 | G20: 27605 | H20: 32576 | I20: 34076 | J20: 32708 | K20: 39789 | L20: 39819 | M20: 40141
B21: Pension Costs | C21: 630 | D21: 2132 | E21: 804 | F21: 819 | G21: 3338 | H21: 1144 | I21: 2155 | J21: 3838 | K21: 2776 | L21: 3082 | M21: 4591
B22: Total Staffing Costs | C22: =SUM(C19:C21) -> 143749 | D22: =SUM(D19:D21) -> 166085 | E22: =SUM(E19:E21) -> 208258 | F22: =SUM(F19:F21) -> 207526 | G22: =SUM(G19:G21) -> 263615 | H22: =SUM(H19:H21) -> 309917 | I22: =SUM(I19:I21) -> 325572 | J22: =SUM(J19:J21) -> 314354 | ... M22: =SUM(M19:M21) -> 386086
B25: Key Ratios
B26: Staff / Revenue | D26: ='Income Statement'!C7/D12 -> 0.46855346 | E26: ='Income Statement'!D7/E12 -> 0.431 | F26: ='Income Statement'!E7/F12 -> 0.49591837 | G26: ='Income Statement'!F7/G12 -> 0.5437276 | H26: ='Income Statement'!G7/H12 -> 0.62485346 | I26: ='Income Statement'!H7/I12 -> 0.55670455 | J26: ='Income Statement'!I7/J12 -> 0.50549793 | K26: ='Income Statement'!J7/K12 -> 0.59134328 | ... M26: ='Income Statement'!L7/M12 -> 0.60712166
B29: Key Insights
B30: Name | C30: Data #1 | D30: Data #2 | E30: Purpose | F30: Chart Type
B31: Highest Paid Director | C31: Highest Paid Director | D31: Years | E31: Show how the top executive’s remuneration has changed over time | F31: Clustered vertical column chart - (X = Year; Y = Highest paid director’s total pay in £m)
B32: Full Time Staff | C32: Total Full Time Staff (headcount) | D32: Years | E32: Illustrate the trend in overall workforce size year-on-year | F32: Single-series line chart - (X = Year; Y = FTE headcount)
B33: Staffing Costs | C33: Total Staffing Costs | D33: Years | E33: Track how total payroll expense evolves as the business grows | F33: Single-series column chart - (X = Year; Y = Total staffing cost in £m)

Sheet Income Statement
B2: Income Statement
B3: Liverpool FC | C3: 2015 | D3: 2016 | E3: 2017 | F3: 2018 | G3: 2019 | H3: 2020 | I3: 2021 | J3: 2022 | K3: 2023 | L3: 2024
B4: Broadcasting | C4: 122.6 | D4: 123.6 | E4: 154.4 | F4: 220.1 | G4: 260.8 | H4: 201.6 | I4: 266.1 | J4: 260.8 | K4: 241.6 | L4: 203.7
B5: Matchday | C5: 59 | D5: 62.4 | E5: 73.5 | F5: 80.7 | G5: 188 | H5: 70.9 | I5: 3.6 | J5: 86.8 | K5: 272.5 | L5: 101.7
B6: Commercial | C6: 116.4 | D6: 115.7 | E6: 136.6 | F6: 154.3 | G6: 84.2 | H6: 217.4 | I6: 217.6 | J6: 246.7 | K6: 79.8 | L6: 308.4
B7: Total Revenue | C7: =SUM(C4:C6) -> 298 | D7: =SUM(D4:D6) -> 301.7 | E7: =SUM(E4:E6) -> 364.5 | F7: =SUM(F4:F6) -> 455.1 | G7: =SUM(G4:G6) -> 533 | H7: =SUM(H4:H6) -> 489.9 | I7: =SUM(I4:I6) -> 487.3 | J7: =SUM(J4:J6) -> 594.3 | ... L7: =SUM(L4:L6) -> 613.8
B8: Cost of sales | C8: 28.23 | D8: 29.8 | E8: 37.6 | F8: 42.5 | G8: 48 | H8: 63.2 | I8: 51.5 | J8: 67.3 | K8: 70.5 | L8: 83.4
B9: Gross Profit | C9: =C7-C8 -> 269.77 | D9: =D7-D8 -> 271.9 | E9: =E7-E8 -> 326.9 | F9: =F7-F8 -> 412.6 | G9: =G7-G8 -> 485 | H9: =H7-H8 -> 426.7 | I9: =I7-I8 -> 435.8 | J9: =J7-J8 -> 527 | ... L9: =L7-L8 -> 530.4
B10: Other Operating Income | C10: 0 | D10: 0 | E10: 0 | F10: 0 | G10: 0 | H10: 0 | I10: 0 | J10: 0 | K10: 0 | L10: 0
B11: Wages & Salaries | C11: -166.1 | D11: -208.3 | E11: -208.3 | F11: -263.6 | G11: -309.9 | H11: -325.6 | I11: -314.4 | J11: -366.1 | K11: -372.9 | L11: -386.1
B12: Other Operating Expenses | C12: -58.9 | D12: -58.2 | E12: -82.7 | F12: -96.8 | G12: -99.7 | H12: -122.6 | I12: -95.8 | J12: -131.8 | K12: -137.2 | L12: -167.1
B13: Expenses | C13: =SUM(C11:C12) -> -225 | D13: =SUM(D11:D12) -> -266.5 | E13: =SUM(E11:E12) -> -291 | F13: =SUM(F11:F12) -> -360.4 | G13: =SUM(G11:G12) -> -409.6 | H13: =SUM(H11:H12) -> -448.2 | I13: =SUM(I11:I12) -> -410.2 | J13: =SUM(J11:J12) -> -497.9 | ... L13: =SUM(L11:L12) -> -553.2
B14: ADJ Ebitda | C14: =C7+(SUM(C11:C12)) -> 73 | D14: =D7+(SUM(D11:D12)) -> 35.2 | E14: =E7+(SUM(E11:E12)) -> 73.5 | F14: =F7+(SUM(F11:F12)) -> 94.7 | G14: =G7+(SUM(G11:G12)) -> 123.4 | H14: =H7+(SUM(H11:H12)) -> 41.7 | I14: =I7+(SUM(I11:I12)) -> 77.1 | J14: =J7+(SUM(J11:J12)) -> 96.4 | K14: =K7+K10+K13 -> 83.8 | L14: =L7+(SUM(L11:L12)) -> 60.6
B15: Player Amortization | C15: -59.2 | D15: -64.5 | E15: -58.4 | F15: -77.1 | G15: -111.8 | H15: -106 | I15: -107.8 | J15: -102.7 | K15: -107.5 | L15: -114.5
B16: Player Impairement | C16: -0.3 | D16: -7.9 | E16: 0 | F16: -0.3 | G16: -0.5 | H16: 0 | I16: -0.5 | J16: -0.2 | K16: -2.1 | L16: -0.6
B17: Depreciation | C17: -3.3 | D17: -4 | E17: -7.2 | F17: -8.9 | G17: -9.4 | H17: -8.7 | I17: -8.9 | J17: -11.4 | K17: -12.1 | L17: -15.2
B18: Property Impairement | C18: 0 | D18: 0 | E18: 0 | F18: 0 | G18: 0 | H18: 0 | I18: 0 | J18: 0 | K18: 0 | L18: 0
B19: Goodwill Amortiziation & Other | C19: -1.3 | D19: -1.3 | E19: -1.3 | F19: -1.3 | G19: -1.2 | H19: -1.3 | I19: -0.2 | J19: 0 | K19: 0 | L19: 0
B20: Non Cash Flow Expenses | C20: =SUM(C15:C19) -> -64.1 | D20: =SUM(D15:D19) -> -77.7 | E20: =SUM(E15:E19) -> -66.9 | F20: =SUM(F15:F19) -> -87.6 | G20: =SUM(G15:G19) -> -122.9 | H20: =SUM(H15:H19) -> -116 | I20: =SUM(I15:I19) -> -117.4 | J20: =SUM(J15:J19) -> -114.3 | ... L20: =SUM(L15:L19) -> -130.3
B21: ADJ EBIT | C21: =C14+(SUM(C15:C19)) -> 8.9 | D21: =D14+(SUM(D15:D19)) -> -42.5 | E21: =E14+(SUM(E15:E19)) -> 6.6 | F21: =F14+(SUM(F15:F19)) -> 7.1 | G21: =G14+(SUM(G15:G19)) -> 0.5 | H21: =H14+(SUM(H15:H19)) -> -74.3 | I21: =I14+(SUM(I15:I19)) -> -40.3 | J21: =J14+(SUM(J15:J19)) -> -17.9 | K21: =K14+K20 -> -37.9 | L21: =L14+(SUM(L15:L19)) -> -69.7
B22: Exceptional Items | C22: 0.3 | D22: -15.7 | E22: 0 | F22: 0 | G22: 0 | H22: 0 | I22: 0 | J22: 0 | K22: 0 | L22: 0
B23: Player Sale Profit | C23: 54.2 | D23: 42.1 | E23: 38.3 | F23: 123.9 | G23: 45.2 | H23: 26.9 | I23: 39.3 | J23: 28.1 | K23: 33.8 | L23: 22
B24: Asset Sale Profit | C24: 0 | D24: 0 | E24: 0 | F24: 0 | G24: 0 | H24: 4 | I24: -0.2 | J24: -0.2 | K24: -0.4 | L24: 0.1
B25: Operating Profit/(Loss) | C25: =C21+(C22)+(SUM(C23:C24)) -> 63.4 | D25: =D21+(D22)+(SUM(D23:D24)) -> -16.1 | E25: =E21+(E22)+(SUM(E23:E24)) -> 44.9 | F25: =F21+(F22)+(SUM(F23:F24)) -> 131 | G25: =G21+(G22)+(SUM(G23:G24)) -> 45.7 | H25: =H21+(H22)+(SUM(H23:H24)) -> -43.4 | I25: =I21+(I22)+(SUM(I23:I24)) -> -1.2 | J25: =J21+(J22)+(SUM(J23:J24)) -> 10 | ... L25: =L21+(L22)+(SUM(L23:L24)) -> -47.6
B26: Finance Income | C26: 0 | D26: 0 | E26: 0 | F26: 0 | G26: 1.1 | H26: 0.7 | I26: 0.5 | J26: 0.9 | K26: 1.6 | L26: 3.2
B27: Finance Expenses | C27: -4.3 | D27: -3.9 | E27: -5.4 | F27: -6 | G27: -5 | H27: -3.7 | I27: -4.3 | J27: -3.5 | K27: -6.2 | L27: -12.6
B28: Net Interest Payable | C28: =C26+C27 -> -4.3 | D28: =D26+D27 -> -3.9 | E28: =E26+E27 -> -5.4 | F28: =F26+F27 -> -6 | G28: =G26+G27 -> -3.9 | H28: =H26+H27 -> -3 | I28: =I26+I27 -> -3.8 | J28: =J26+J27 -> -2.6 | ... L28: =L26+L27 -> -9.4
B29: Profit/(Loss) before Tax | C29: =(C25+C26)+C27 -> 59.1 | D29: =(D25+D26)+D27 -> -20 | E29: =(E25+E26)+E27 -> 39.5 | F29: =(F25+F26)+F27 -> 125 | G29: =(G25+G26)+G27 -> 41.8 | H29: =(H25+H26)+H27 -> -46.4 | I29: =(I25+I26)+I27 -> -5 | J29: =(J25+J26)+J27 -> 7.4 | ... L29: =(L25+L26)+L27 -> -57
B30: Tax Income/(Expense) | C30: -0.5 | D30: -1.5 | E30: -0.6 | F30: -19.1 | G30: -8.5 | H30: 6.9 | I30: -4.8 | J30: -5 | K30: 2.1 | L30: 13.6
B31: Profit/(Loss) after Tax | C31: =C29+C30 -> 58.6 | D31: =D29+D30 -> -21.5 | E31: =E29+E30 -> 38.9 | F31: =F29+F30 -> 105.9 | G31: =G29+G30 -> 33.3 | H31: =H29+H30 -> -39.5 | I31: =I29+I30 -> -9.8 | J31: =J29+J30 -> 2.4 | ... L31: =L29+L30 -> -43.4
B34: Key Ratios
B35: Wages to Revenue | C35: =ABS(C11/C7) -> 0.55738255 | D35: =ABS(D11/D7) -> 0.69042095 | E35: =ABS(E11/E7) -> 0.57146776 | F35: =ABS(F11/F7) -> 0.57921336 | G35: =ABS(G11/G7) -> 0.58142589 | H35: =ABS(H11/H7) -> 0.66462543 | I35: =ABS(I11/I7) -> 0.64518777 | J35: =ABS(J11/J7) -> 0.61601885 | ... L35: =ABS(L11/L7) -> 0.62903226
B36: Wages + Player Amort'n | C36: =C11+C15 -> -225.3 | D36: =D11+D15 -> -272.8 | E36: =E11+E15 -> -266.7 | F36: =F11+F15 -> -340.7 | G36: =G11+G15 -> -421.7 | H36: =H11+H15 -> -431.6 | I36: =I11+I15 -> -422.2 | J36: =J11+J15 -> -468.8 | ... L36: =L11+L15 -> -500.6
B37: Wages + Player Amort'n to Revenue | C37: =ABS(C36/C7) -> 0.75604027 | D37: =ABS(D36/D7) -> 0.90420948 | E37: =ABS(E36/E7) -> 0.73168724 | F37: =ABS(F36/F7) -> 0.74862668 | G37: =ABS(G36/G7) -> 0.79118199 | H37: =ABS(H36/H7) -> 0.88099612 | I37: =ABS(I36/I7) -> 0.86640673 | J37: =ABS(J36/J7) -> 0.78882719 | ... L37: =ABS(L36/L7) -> 0.81557511
B38: WAI / (Revenue + Player Sale Profit) | C38: =C36/(C7+C23) -> -0.63969336 | D38: =D36/(D7+D23) -> -0.79348458 | E38: =E36/(E7+E23) -> -0.66211519 | F38: =F36/(F7+F23) -> -0.58842832 | G38: =G36/(G7+G23) -> -0.72933241 | H38: =H36/(H7+H23) -> -0.83513932 | I38: =I36/(I7+I23) -> -0.80174706 | J38: =J36/(J7+J23) -> -0.75321337 | ... L38: =L36/(L7+L23) -> -0.78735451
B39: Other Expenses to Revenue | C39: =ABS(C12/C7) -> 0.19765101 | D39: =ABS(D12/D7) -> 0.19290686 | E39: =ABS(E12/E7) -> 0.22688615 | F39: =ABS(F12/F7) -> 0.21270051 | G39: =ABS(G12/G7) -> 0.18705441 | H39: =ABS(H12/H7) -> 0.25025515 | I39: =ABS(I12/I7) -> 0.19659347 | J39: =ABS(J12/J7) -> 0.22177352 | ... L39: =ABS(L12/L7) -> 0.27223851
B40: Adjusted EBITDA Margin | C40: =C14/C7 -> 0.24496644 | D40: =D14/D7 -> 0.11667219 | E40: =E14/E7 -> 0.20164609 | F40: =F14/F7 -> 0.20808613 | G40: =G14/G7 -> 0.2315197 | H40: =H14/H7 -> 0.085119412 | I40: =I14/I7 -> 0.15821876 | J40: =J14/J7 -> 0.16220764 | ... L40: =L14/L7 -> 0.098729228
B44: Key Insights
B45: Name | C45: Data #1 | D45: Data #2 | E45: Data #3 | F45: Data #4 | G45: Purpose | H45: Chart Type
B46: Profit/(Loss) before Tax | C46: Profit / (Loss) before tax | D46: Years | G46: Show how the club’s pre-tax profitability swings from year to year | H46: Clustered vertical column chart (X = Year; Y = £ Profit/(Loss) before tax)
...

Sheet Balance Sheet
B2: Balance Sheet
B3: Liverpool FC | C3: 2015 | D3: 2016 | E3: 2017 | F3: 2018 | G3: 2019 | H3: 2020 | I3: 2021 | J3: 2022 | K3: 2023 | L3: 2024 | Q3: *Only shows Debt + Player Trading*
B4: Player Trading
B5: Player Purchases | C5: 135 | D5: 101.8 | E5: 76.3 | F5: 195.2 | G5: 223 | H5: 29.3 | I5: 136.1 | J5: 68.7 | K5: 133.5 | L5: 194.4 | Q5: Need to add infastructure investment
B6: Player Sales | C6: 75.2 | D6: 49.3 | E6: 72.6 | F6: 137.1 | G6: 59.7 | H6: 29.4 | I6: 42.9 | J6: 32.6 | K6: 44.1 | L6: 36.8
B7: Net Spend / (Sales) | C7: =C5-C6 -> 59.8 | D7: =D5-D6 -> 52.5 | E7: =E5-E6 -> 3.7 | F7: =F5-F6 -> 58.1 | G7: =G5-G6 -> 163.3 | H7: =H5-H6 -> -0.1 | I7: =I5-I6 -> 93.2 | J7: =J5-J6 -> 36.1 | ... L7: =L5-L6 -> 157.6
B8: Squad Cost | C8: 316.4 | D8: 360.1 | E8: 332.5 | F8: 485 | G8: 646.5 | H8: 634.1 | I8: 708.9 | J8: 729.3 | K8: 787.1 | L8: 749.4 | P8: Net Assets
P9: Assets | Q9: 721
B10: Debt | P10: Liabilities | Q10: 526
B11: Owner Debt | C11: 49.4 | D11: 110 | E11: 109.9 | F11: 99.9 | G11: 79.3 | H11: 71.4 | I11: 71.4 | J11: 71.4 | K11: 71.4 | L11: 198.7 | P11: Net Assets | Q11: =Q9-Q10 -> 195
B12: External Debt | C12: 49.5 | D12: 53.3 | E12: 71.7 | F12: 55.1 | G12: 49.5 | H12: 197 | I12: 126.9 | J12: 87.1 | K12: 125.4 | L12: 115.6
B13: Gross Debt | C13: =C11+C12 -> 98.9 | D13: =D11+D12 -> 163.3 | E13: =E11+E12 -> 181.6 | F13: =F11+F12 -> 155 | G13: =G11+G12 -> 128.8 | H13: =H11+H12 -> 268.4 | I13: =I11+I12 -> 198.3 | J13: =J11+J12 -> 158.5 | ... L13: =L11+L12 -> 314.3
B14: Cash | C14: 4.1 | D14: 8.2 | E14: 4 | F14: 10.3 | G14: 37.5 | H14: 149.3 | I14: 31.5 | J14: 13.5 | K14: 3.4 | L14: 7.5
B15: Net Debt/ (Funds) | C15: =C13-C14 -> 94.8 | D15: =D13-D14 -> 155.1 | E15: =E13-E14 -> 177.6 | F15: =F13-F14 -> 144.7 | G15: =G13-G14 -> 91.3 | H15: =H13-H14 -> 119.1 | I15: =I13-I14 -> 166.8 | J15: =J13-J14 -> 145 | ... L15: =L13-L14 -> 306.8
B16: Transfer Debt | C16: 78.8 | D16: 88.6 | E16: 71.3 | F16: 141.4 | G16: 171.9 | H16: 77.7 | I16: 121.9 | J16: 93.7 | K16: 112.4 | L16: 127.8
B17: Transfer Receivables | C17: 76.2 | D17: 51.2 | E17: 66.2 | F17: 111.7 | G17: 54.2 | H17: 46.5 | I17: 54.5 | J17: 55.1 | K17: 66.6 | L17: 57.9
B18: Net Transfer Debt / (Funds) | C18: =C16-C17 -> 2.6 | D18: =D16-D17 -> 37.4 | E18: =E16-E17 -> 5.1 | F18: =F16-F17 -> 29.7 | G18: =G16-G17 -> 117.7 | H18: =H16-H17 -> 31.2 | I18: =I16-I17 -> 67.4 | J18: =J16-J17 -> 38.6 | ... L18: =L16-L17 -> 69.9
B19: Total Debt | C19: =C16+C13 -> 177.7 | D19: =D16+D13 -> 251.9 | E19: =E16+E13 -> 252.9 | F19: =F16+F13 -> 296.4 | G19: =G16+G13 -> 300.7 | H19: =H16+H13 -> 346.1 | I19: =I16+I13 -> 320.2 | J19: =J16+J13 -> 252.2 | ... L19: =L16+L13 -> 442.1
B21: Net Financial Debt | C21: =C15 -> 94.8 | D21: =D15 -> 155.1 | E21: =E15 -> 177.6 | F21: =F15 -> 144.7 | G21: =G15 -> 91.3 | H21: =H15 -> 119.1 | I21: =I15 -> 166.8 | J21: =J15 -> 145 | ... L21: =L15 -> 306.8
B22: Net Transfer Debt | C22: =C18 -> 2.6 | D22: =D18 -> 37.4 | E22: =E18 -> 5.1 | F22: =F18 -> 29.7 | G22: =G18 -> 117.7 | H22: =H18 -> 31.2 | I22: =I18 -> 67.4 | J22: =J18 -> 38.6 | ... L22: =L18 -> 69.9
B23: Football Net Debt | C23: =C21+C22 -> 97.4 | D23: =D21+D22 -> 192.5 | E23: =E21+E22 -> 182.7 | F23: =F21+F22 -> 174.4 | G23: =G21+G22 -> 209 | H23: =H21+H22 -> 150.3 | I23: =I21+I22 -> 234.2 | J23: =J21+J22 -> 183.6 | ... L23: =L21+L22 -> 376.7
B24: FND less Owner Debt | C24: =C23-C11 -> 48 | D24: =D23-D11 -> 82.5 | E24: =E23-E11 -> 72.8 | F24: =F23-F11 -> 74.5 | G24: =G23-G11 -> 129.7 | H24: =H23-H11 -> 78.9 | I24: =I23-I11 -> 162.8 | J24: =J23-J11 -> 112.2 | ... L24: =L23-L11 -> 178
B26: Contingent Transfer Fees
B27: Contingent Fees Payable | C27: 12.7 | D27: 17.1 | E27: 18.5 | F27: 38.2 | G27: 22.1 | H27: 10.8 | I27: 23.8 | J27: 33.7 | K27: 55.9 | L27: 41.6
B28: Contenget Fees Receivable | C28: 4.1 | D28: 8.2 | E28: 19.2 | F28: 35.7 | G28: 11.2 | H28: 9.6 | I28: 7.3 | J28: 3.5 | K28: 12.7 | L28: 2.5
B29: Net Unment Add-ons | C29: =C27-C28 -> 8.6 | D29: =D27-D28 -> 8.9 | E29: =E27-E28 -> -0.7 | F29: =F27-F28 -> 2.5 | G29: =G27-G28 -> 10.9 | H29: =H27-H28 -> 1.2 | I29: =I27-I28 -> 16.5 | J29: =J27-J28 -> 30.2 | ... L29: =L27-L28 -> 39.1
B31: Key Ratios
B32: Net Debt / Adj EBITDA | C32: =C15/'Income Statement'!C14 -> 1.2986301 | D32: =D15/'Income Statement'!D14 -> 4.40625 | E32: =E15/'Income Statement'!E14 -> 2.4163265 | F32: =F15/'Income Statement'!F14 -> 1.5279831 | G32: =G15/'Income Statement'!G14 -> 0.73987034 | H32: =H15/'Income Statement'!H14 -> 2.8561151 | I32: =I15/'Income Statement'!I14 -> 2.1634241 | J32: =J15/'Income Statement'!J14 -> 1.5041494 | ... L32: =L15/'Income Statement'!L14 -> 5.0627063
B33: Net Bank Debt / Adj EBITDA | C33: =C12/'Income Statement'!C14 -> 0.67808219 | D33: =D12/'Income Statement'!D14 -> 1.5142045 | E33: =E12/'Income Statement'!E14 -> 0.9755102 | F33: =F12/'Income Statement'!F14 -> 0.58183738 | G33: =G12/'Income Statement'!G14 -> 0.40113452 | H33: =H12/'Income Statement'!H14 -> 4.7242206 | I33: =I12/'Income Statement'!I14 -> 1.6459144 | J33: =J12/'Income Statement'!J14 -> 0.90352697 | ... L33: =L12/'Income Statement'!L14 -> 1.9075908
B36: Key Insights Derived
B37: Name | C37: Data #1 | D37: Data #2 | E37: Data #3 | F37: Purpose | G37: Chart Type
B38: Player Amortisation & Impairement | C38: Player Amortisation | D38: Player Impairement | E38: Years | F38: Show annual club expense | G38: Clustered column chart – bars for amortisation vs impairment
B39: Depreciation | C39: Depreciation | D39: Years | F39: Show annual depreciation | G39: Clustered column chart – vertical bars over years
B40: *Other individual stats* | C40: (EG Player Purchases, Owner Debt, Etc) | D40: Years | F40: Trend analysis | G40: Clustered column chart
B41: Transfer Spend | C41: Player Purchases | D41: Player Sales | E41: Net Spend | F41: Show transfer activity | G41: Combo chart: clustered columns for purchases & sales + line for net spend | O41: Example here:
B42: Squad Cost | C42: Squad Cost | D42: Years | F42: Show squad cost trend | G42: Line chart – squad cost by year
B43: Gross Financial Debt | C43: Gross Debt | D43: Years | F43: Historical debt levels | G43: Line chart – gross financial debt over time
B44: Transfer Debt | C44: Transfer Payables | D44: Transfer Receivables | E44: Net Transfer Debt | F44: Historical transfer debt | G44: Clustered column chart – payables vs receivables vs net debt (as line) | O44: Same as above:
B45: Net Financial Leverage Ratios | C45: Net Debt / Adj EBITDA | D45: Net Bank Debt / Adj EBITDA | E45: Years | F45: Show leverage over time | G45: Multi-line chart – one line per ratio (use secondary axis if scales differ)
B46: Football Net Debt | C46: Net Financial Debt | D46: Net Transfer Debt | E46: FND less Owner Debt | F46: Debt‐breakdown analysis | G46: 100% stacked column chart – components of total FND each year | O46: Example here:

Sheet Cash Flow Statement V1
B2: Cash Flow Statement
B3: Liverpool FC | C3: 2015 | D3: 2016 | E3: 2017 | F3: 2018 | G3: 2019 | H3: 2020 | I3: 2021 | J3: 2022 | K3: 2023 | L3: 2024
B4: Cash Flow From Operations
B5: Operating Profit / (Loss) | C5: ='Income Statement'!C21 -> 8.9 | D5: ='Income Statement'!D21 -> -42.5 | E5: ='Income Statement'!E21 -> 6.6 | F5: ='Income Statement'!F21 -> 7.1 | G5: ='Income Statement'!G21 -> 0.5 | H5: ='Income Statement'!H21 -> -74.3 | I5: ='Income Statement'!I21 -> -40.3 | J5: ='Income Statement'!J21 -> -17.9 | ... L5: ='Income Statement'!L21 -> -69.7 | Q5: Use Of Funds Data
B6: Depreciation, Amortization & Impairement | C6: =ABS('Income Statement'!C20) -> 64.1 | D6: =ABS('Income Statement'!D20) -> 77.7 | E6: =ABS('Income Statement'!E20) -> 66.9 | F6: =ABS('Income Statement'!F20) -> 87.6 | G6: =ABS('Income Statement'!G20) -> 122.9 | H6: =ABS('Income Statement'!H20) -> 116 | I6: =ABS('Income Statement'!I20) -> 117.4 | J6: =ABS('Income Statement'!J20) -> 114.3 | ... L6: =ABS('Income Statement'!L20) -> 130.3 | Q6: Net Cash Interest Payments | R6: =ABS(SUM(C15:L15)) -> 30.9
B7: Profit on disposal of registrations | C7: 0 | D7: ='Income Statement'!D23 -> 42.1 | E7: ='Income Statement'!E23 -> 38.3 | F7: ='Income Statement'!F23 -> 123.9 | G7: ='Income Statement'!G23 -> 45.2 | H7: ='Income Statement'!H23 -> 26.9 | I7: ='Income Statement'!I23 -> 39.3 | J7: ='Income Statement'!J23 -> 28.1 | K7: ='Income Statement'!K23 -> 33.8 | L7: ='Income Statement'!L23 -> 22 | Q7: Net Player Trading | R7: =ABS(SUM(C22:L22)) -> 669.4
B8: Adjusted EBITDA | C8: =C5+C6-C7 -> 73 | D8: =D5+D6-D7 -> -6.9 | E8: =E5+E6-E7 -> 35.2 | F8: =F5+F6-F7 -> -29.2 | G8: =G5+G6-G7 -> 78.2 | H8: =H5+H6-H7 -> 14.8 | I8: =I5+I6-I7 -> 37.8 | J8: =J5+J6-J7 -> 68.3 | ... L8: =L5+L6-L7 -> 38.6 | Q8: Capex | R8: =ABS(SUM(C23:L23)) -> 357.75
B9: Exceptional Cash Expenses | C9: ='Income Statement'!C22 -> 0.3 | D9: ='Income Statement'!D22 -> -15.7 | E9: ='Income Statement'!E22 -> 0 | F9: ='Income Statement'!F22 -> 0 | G9: ='Income Statement'!G22 -> 0 | H9: ='Income Statement'!H22 -> 0 | I9: ='Income Statement'!I22 -> 0 | J9: ='Income Statement'!J22 -> 0 | ... L9: ='Income Statement'!L22 -> 0
B10: CFO before △ in working capital | C10: =C8-C9 -> 72.7 | D10: =D8-D9 -> 8.8 | E10: =E8+E9 -> 35.2 | F10: =F8+F9 -> -29.2 | G10: =G8+G9 -> 78.2 | H10: =H8+H9 -> 14.8 | I10: =I8+I9 -> 37.8 | J10: =J8+J9 -> 68.3 | K10: =K8+K9 -> 50 | L10: =L8+L9 -> 38.6
B11: Change in Working Capital | C11: -7.62 | D11: 12.7 | G11: 7.4 | H11: 52.1 | I11: -54 | J11: 16.3 | K11: 5.1 | L11: 22.6
B12: *Above to be edited.*
B14: CFO before Interest and Tax | C14: 64.6 | D14: 39.1 | E14: 73.5 | F14: 103.1 | G14: 130.8 | H14: 93.9 | I14: 23.1 | J14: 112.7 | K14: 88.9 | L14: 83.7
B15: Net Cash Interest Payments | C15: -2.8 | D15: -2.3 | E15: -2.5 | F15: -1.8 | G15: -1.8 | H15: -1.8 | I15: -3.3 | J15: -2.2 | K15: -4.1 | L15: -8.3
B16: Tax Payments | C16: 0 | D16: 0 | E16: 0 | F16: 0 | G16: 0 | H16: 0 | I16: 0 | J16: 0 | K16: 0 | L16: 0
B17: Cash Flow from Operations | C17: =C14+C15+C16 -> 61.8 | D17: =D14+D15+D16 -> 36.8 | E17: =E14+E15+E16 -> 71 | F17: =F14+F15+F16 -> 101.3 | G17: =G14+G15+G16 -> 129 | H17: =H14+H15+H16 -> 92.1 | I17: =I14+I15+I16 -> 19.8 | J17: =J14+J15+J16 -> 110.5 | ... L17: =L14+L15+L16 -> 75.4
B19: Cash Flow From Investing
B20: Player sales | C20: 36.9 | D20: 62 | E20: 58.4 | F20: 104.9 | G20: 114.8 | H20: 32 | I20: 34.5 | J20: 32.2 | K20: 39.1 | L20: 49.1
B21: Players Purchases | C21: -95.6 | D21: -99.8 | E21: -97.2 | F21: -154.1 | G21: -173.9 | H21: -121.5 | I21: -90.2 | J21: -97.2 | K21: -122.2 | L21: -181.6
B22: Net Player Trading | C22: =C20+C21 -> -58.7 | D22: =D20+D21 -> -37.8 | E22: =E20+E21 -> -38.8 | F22: =F20+F21 -> -49.2 | G22: =G20+G21 -> -59.1 | H22: =H20+H21 -> -89.5 | I22: =I20+I21 -> -55.7 | J22: =J20+J21 -> -65 | ... L22: =L20+L21 -> -132.5
B23: Capex | C23: -39.6 | D23: -57.4 | E23: -52 | F23: -15.9 | G23: -22.6 | H23: -29.7 | I23: -11.35 | J23: -23.4 | K23: -49.8 | L23: -56
B24: Cash Flow from Investing | C24: =C20+C21+C23 -> -98.3 | D24: =D20+D21+D23 -> -95.2 | E24: =E20+E21+E23 -> -90.8 | F24: =F20+F21+F23 -> -65.1 | G24: =G20+G21+G23 -> -81.7 | H24: =H20+H21+H23 -> -119.2 | I24: =I20+I21+I23 -> -67.05 | J24: =J20+J21+J23 -> -88.4 | ... L24: =L20+L21+L23 -> -188.5
B25: Cash Flow before Financing | C25: =C17+C24 -> -36.5 | D25: =D17+D24 -> -58.4 | E25: =E17+E24 -> -19.8 | F25: =F17+F24 -> 36.2 | G25: =G17+G24 -> 47.3 | H25: =H17+H24 -> -27.1 | I25: =I17+I24 -> -47.25 | J25: =J17+J24 -> 22.1 | ... L25: =L17+L24 -> -113.1
B27: Cash Flow from Financing
B28: Owner Loans | C28: 49 | D28: 59.6 | E28: -2.4 | F28: -12.9 | G28: -14 | H28: -7.9 | I28: 0 | J28: 0 | K28: 0 | L28: 127.3
B29: Share Capital | C29: 0 | D29: 0 | E29: 0 | F29: 0 | G29: 0 | H29: 0 | I29: 0 | J29: 0 | K29: 0 | L29: 0
B30: Dividends | C30: 0 | D30: 0 | E30: 0 | F30: 0 | G30: 0 | H30: 0 | I30: 0 | J30: 0 | K30: 0 | L30: 0
B31: Owner Financing | C31: =SUM(C28:C30) -> 49 | D31: =SUM(D28:D30) -> 59.6 | E31: =SUM(E28:E30) -> -2.4 | F31: =SUM(F28:F30) -> -12.9 | G31: =SUM(G28:G30) -> -14 | H31: =SUM(H28:H30) -> -7.9 | I31: =SUM(I28:I30) -> 0 | J31: =SUM(J28:J30) -> 0 | ... L31: =SUM(L28:L30) -> 127.3
B32: Net Bank Loans (Repayments) | C32: -9 | D32: 3 | E32: 18 | F32: -17 | G32: -6 | H32: 146.9 | I32: -70.4 | J32: -40 | K32: 38 | L32: -10.2
B33: Cash Flow from Financing | C33: =C31+C32 -> 40 | D33: =D31+D32 -> 62.6 | E33: =E31+E32 -> 15.6 | F33: =F31+F32 -> -29.9 | G33: =G31+G32 -> -20 | H33: =H31+H32 -> 139 | I33: =I31+I32 -> -70.4 | J33: =J31+J32 -> -40 | ... L33: =L31+L32 -> 117.1
B35: Net Cash Flow | C35: =C17+C24+C33 -> 3.5 | D35: =D17+D24+D33 -> 4.2 | E35: =E17+E24+E33 -> -4.2 | F35: =F17+F24+F33 -> 6.3 | G35: =G17+G24+G33 -> 27.3 | H35: =H17+H24+H33 -> 111.9 | I35: =I17+I24+I33 -> -117.65 | J35: =J17+J24+J33 -> -17.9 | ... L35: =L17+L24+L33 -> 4
B36: Cash: Start of Year | D36: =C37 -> 3.5 | E36: =D37 -> 7.7 | F36: =E37 -> 3.5 | G36: =F37 -> 9.8 | H36: =G37 -> 37.1 | I36: =H37 -> 149 | J36: =I37 -> 31.35 | K36: =J37 -> 13.45 | L36: =K37 -> 3.35
B37: Cash: End of Year | C37: =C36+C35 -> 3.5 | D37: =D36+D35 -> 7.7 | E37: =E36+E35 -> 3.5 | F37: =F36+F35 -> 9.8 | G37: =G36+G35 -> 37.1 | H37: =H36+H35 -> 149 | I37: =I36+I35 -> 31.35 | J37: =J36+J35 -> 13.45 | ... L37: =L36+L35 -> 7.35
B42: Key Insights Derived
B43: Name | C43: Data #1 | D43: Data #2 | E43: Data #3 | F43: Data #4 | G43: Purpose | H43: Chart Type
B44: Cash Balance | C44: Cash Balance | D44: Years | G44: Show how the club’s closing cash position moves year-on-year | H44: Line chart (X = Year; Y = Cash balance £m)
B45: Use of Funds | C45: Player Purchases (net) | D45: Capex | E45: Interest | F45: Years | G45: Compare the club’s main cash outflows in each period | H45: Stacked column chart (X = Year; stacked series = Net purchases, Capex, Interest) | P45: Example here:
B46: Owner Funding | C46: Owner Funding | D46: Years | G46: Illustrate equity injections or owner loans provided over time | H46: Clustered column chart (X = Year; Y = Owner funding £m)
B47: Cash Flow From Operations | C47: Cash Flow From Operations | D47: Years | G47: Track the club’s cash generation from core operations | H47: Line chart (X = Year; Y = CFO £m)
B48: Cash flow before financing | C48: Cash flow before financing | D48: Years | G48: Show cash available prior to any financing-related inflows/outflows | H48: Line chart (X = Year; Y = Cash flow pre-financing £m)
B49: Net Capex | C49: Net capex | D49: Net capex / revenue (%) | E49: Years | G49: Combine absolute net capex with its share of revenues to gauge investment intensity | H49: Combo chart: clustered columns for Net Capex (£m) + line for Net Capex/Revenue (%)
...

Sheet Comps
B2: Comps
B3: Title | C3: Data Point #1 | D3: Data Point #2 | E3: Against | F3: Chart Type 1 Yr | G3: Chart Type 5-10Yrs
B4: Profit/ (Loss) before Tax | C4: Profit/ (Loss) before Tax | D4: 1Yr (individual season) / 5-10 yrs | E4: Comp Basket / League | F4: Horizontal bar chart – rank clubs by metric | G4: Multi-line chart – one line per club showing metric trend over time
B5: Profit on Player Sales (£M) | C5: Profit on Player Sales | D5: 1Yr (individual season) / 5-10 yrs | E5: Comp Basket / League | F5: Horizontal bar chart – rank clubs by metric | G5: Multi-line chart – one line per club showing metric trend over time
B6: Operating Profit / (Loss) | C6: Operating Profit / (Loss) | D6: 1Yr (individual season) / 5-10 yrs | E6: Comp Basket / League | F6: Horizontal bar chart – rank clubs by metric | G6: Multi-line chart – one line per club showing metric trend over time
B7: EBITDA | C7: EBITDA | D7: 1Yr (individual season) / 5-10 yrs | E7: Comp Basket / League | F7: Horizontal bar chart – rank clubs by metric | G7: Multi-line chart – one line per club showing metric trend over time
B8: Revenue Trend | C8: Revenue | D8: 1Yr (individual season) / 5-10 yrs | E8: Comp Basket / League | F8: Horizontal bar chart – rank clubs by metric | G8: Multi-line chart – one line per club showing metric trend over time
B9: Revenue Segment | C9: Revenue Segment (EG Commercial) | D9: 1Yr (individual season) / 5-10 yrs | E9: Comp Basket / League | F9: Horizontal bar chart – rank clubs by metric | G9: Multi-line chart – one line per club showing metric trend over time
B10: Attendances | C10: Attendance | D10: 1Yr (individual season) / 5-10 yrs | E10: Comp Basket / League | F10: Horizontal bar chart – rank clubs by metric | G10: Multi-line chart – one line per club showing metric trend over time
B11: Wages | C11: Wages | D11: 1Yr (individual season) / 5-10 yrs | E11: Comp Basket / League | F11: Horizontal bar chart – rank clubs by metric | G11: Multi-line chart – one line per club showing metric trend over time
B12: Wages to Turnover | C12: Wages to Turnover | D12: 1Yr (individual season) / 5-10 yrs | E12: Comp Basket / League | F12: Horizontal bar chart – rank clubs by metric | G12: Multi-line chart – one line per club showing metric trend over time
B13: Highest Paid Director | C13: Highest Paid Director | D13: 1Yr (individual season) / 5-10 yrs | E13: Comp Basket / League | F13: Horizontal bar chart – rank clubs by metric | G13: Multi-line chart – one line per club showing metric trend over time
B14: Full Time Staff | C14: Full Time Staff | D14: 1Yr (individual season) / 5-10 yrs | E14: Comp Basket / League | F14: Horizontal bar chart – rank clubs by metric | G14: Multi-line chart – one line per club showing metric trend over time
... B21: WAI to Revenue | C21: WAI to Revenue | D21: 1Yr (individual season) / 5-10 yrs | E21: Comp Basket / League | F21: Horizontal bar chart – rank clubs by metric | G21: Multi-line chart – one line per club showing metric trend over time
B24: Comp Basket
B25: Comparsion clubs that are suggested to draw insights from (For Liverpool FC)
B26: Manchester United
B27: Manchester City
B28: Chelsea
B29: Tottenham
B30: Arsenal

Sheet On The Pitch
B2: Liverpool FC On The Pitch
B3: Season | C3: League | D3: League | E3: UEFA | F3: FA Cup | G3: EFL Cup | H3: Attendance | I3: Capacity | J3: Stadium Utilisation | K3: Squad Cost | L3: Squad Avg Age
B4: 2014/15 | C4: PL | D4: 6th | E4: UEL Round of 32 | F4: Semi-finals | G4: Semi-finals | H4: 44659 | I4: 45276 | J4: =H4/I4 -> 0.98637247 | K4: ='Balance Sheet'!C8 -> 316.4 | L4: 25.3
B5: 2015/16 | C5: PL | D5: 8th | E5: UEL Runners Up | F5: 4th Round | G5: Runners-Up | H5: 43910 | I5: 45276 | J5: =H5/I5 -> 0.96982949 | K5: ='Balance Sheet'!D8 -> 360.1 | L5: 24.9
B6: 2016/17 | C6: PL | D6: 4th | E6: - | F6: 4th Round | G6: Semi-finals | H6: 53016 | I6: 54074 | J6: =H6/I6 -> 0.98043422 | K6: ='Balance Sheet'!E8 -> 332.5 | L6: 25.6
B7: 2017/18 | C7: PL | D7: 4th | E7: UCL Runners Up | F7: 4th Round | G7: 3rd Round | H7: 53049 | I7: 54074 | J7: =H7/I7 -> 0.98104449 | K7: ='Balance Sheet'!F8 -> 485 | L7: 25.5
B8: 2018/19 | C8: PL | D8: 2nd | E8: UCL Winners | F8: 3rd Round | G8: 3rd Round | H8: 52983 | I8: 54074 | J8: =H8/I8 -> 0.97982394 | K8: ='Balance Sheet'!G8 -> 646.5 | L8: 26.6
B9: 2019/20 | C9: PL | D9: 1st | E9: UCL Round of 16 | F9: 5th Round | G9: Quarterfinals | H9: 53143 | I9: 54074 | J9: =H9/I9 -> 0.98278285 | K9: ='Balance Sheet'!H8 -> 634.1 | L9: 26.6
B10: 2020/21 | C10: PL | D10: 3rd | E10: UCL Quarterfinals | F10: 4th Round | G10: 4th Round | H10: 0 | I10: 54074 | J10: =H10/I10 -> 0 | K10: ='Balance Sheet'!I8 -> 708.9 | L10: 26.8
B11: 2021/22 | C11: PL | D11: 2nd | E11: UCL Runners-Up | F11: Winners | G11: Winners | H11: 53008 | I11: 54074 | J11: =H11/I11 -> 0.98028627 | K11: ='Balance Sheet'!J8 -> 729.3 | L11: 27.7
B12: 2022/23 | C12: PL | D12: 5th | E12: UCL Round of 16 | F12: 4th Round | G12: 4th Round | H12: 53184 | I12: 54074 | J12: =H12/I12 -> 0.98354107 | K12: ='Balance Sheet'!K8 -> 787.1 | L12: 27.2
B13: 2023/24 | C13: PL | D13: 3rd | E13: UEL Quaterfinal | F13: Quarterfinals | G13: Winners | H13: 60472 | I13: 61267 | J13: =H13/I13 -> 0.98702401 | K13: ='Balance Sheet'!L8 -> 749.4 | L13: 25.6
B17: Key Insights
B18: Key Insight | C18: Data Point #1 | D18: Data Point #2 | E18: Purpose | F18: Chart Type
B19: Wages-to-Turnover Ratio vs League Place | C19: Wages-to-Turnover (%) | D19: League Place | E19: Show whether clubs that spend a smaller share of revenue on wages tend to finish higher in the table | F19: XY Scatter plot (X = Wages-to-Turnover %; Y = League Position, with axis inverted so 1st place appears at top)
B20: Average Squad Age vs League Place | C20: Average Squad Age | D20: League Place | E20: See if a younger or more experienced squad correlates with a better league finish | F20: XY Scatter plot (X = Average squad age; Y = League Position, inverted axis as above)
B21: Revenue Segment Mix vs League Place | C21: Revenue Segment | D21: League Place | E21: Examine whether certain clubs’ revenue mixes (e.g. broadcast or matchday) increase with success | F21: XY Scatter plot (X = Revenu Segment Metric; Y = League Position, inverted axis as above)

Sheet M&A History
B2: M&A History
B3: Year | C3: Investment Type | D3: Seller | E3: Name | F3: Buyer | G3: Name | H3: Investment (£M) | I3: Equity (%) | J3: Implied EV (£M) | L3: Revenue (£M) | M3: EV / Revenue | N3: EBITDA (£M) | O3: EV / EBITDA | Q3: Buyside Adviser | R3: Sellside Adviser | S3: League Position
B4: 1992 | C4: LSE flotation (IPO) | D4: Moores Family | E4: Founders | F4: Public Investors | G4: Public Investors | H4: 12 | I4: 0.3 | J4: =H4/I4 -> 40 | M4: =J4/L4 -> #DIV/0! | O4: =J4/N4 -> #DIV/0! | Q4: Hambros; SG Warburg‡ | R4: (Company‐run listing) | S4: 6th (’91–’92)
B5: 2007 | C5: Takeover | D5: David Moores / LFC plc | F5: Tom Hicks & George Gillett | H5: 218.9 | I5: 1 | J5: =H5/I5 -> 218.9 | M5: =J5/L5 -> #DIV/0! | O5: =J5/N5 -> #DIV/0! | Q5: Houlihan Lokey | R5: UBS | S5: 3rd (’06–’07)
B6: 2010 | C6: Takeover | D6: Gillett & Hicks (NESV) | F6: Fenway Sports Group | G6: John W. Henry | H6: 300 | I6: 1 | J6: =H6/I6 -> 300 | M6: =J6/L6 -> #DIV/0! | O6: =J6/N6 -> #DIV/0! | Q6: Rotschild | R6: Inner Circle Sports | S6: 7th (’09–’10)
B7: 2011 | C7: Minority Investment | D7: Fenway Sports Group | E7: John W. Henry | F7: Lebron James | H7: 4 | I7: 0.02 | J7: =H7/I7 -> 200 | M7: =J7/L7 -> #DIV/0! | O7: =J7/N7 -> #DIV/0! | S7: 6th (’10–’11)
B8: 2021 | C8: Minority Investment | D8: Fenway Sports Group | E8: John W. Henry | F8: Redbird Capital Partners | G8: Gerry Cardinale | H8: 533 | I8: 0.11 | J8: =H8/I8 -> 4845.4545 | L8: ='Income Statement'!I7 -> 487.3 | M8: =J8/L8 -> 9.9434733 | N8: ='Income Statement'!I14 -> 77.1 | O8: =J8/N8 -> 62.846362 | Q8: Credit Suisse | R8: Fenway in-house | S8: 4th (’20–’21)
B9: 2023 | C9: Minority Investment | D9: Fenway Sports Group | E9: John W. Henry | F9: Dynasty Equity | H9: 147 | I9: 0.0285 | J9: =H9/I9 -> 5157.8947 | L9: ='Income Statement'!K7 -> 593.9 | M9: =J9/L9 -> 8.6847866 | N9: ='Income Statement'!K14 -> 83.8 | O9: =J9/N9 -> 61.550057 | Q9: Morgan Stanley | R9: Fenway in-house | S9: 5th (’22–’23)

Sheet Valuation Calcs
B2: Valuation Calcs | I2: Other Valuation Sources
B3: Revenue Comps | I3: Publication | J3: 2015 | K3: 2016 | L3: 2017 | M3: 2018 | N3: 2019 | O3: 2020 | P3: 2021 | Q3: 2022 | R3: 2023 | S3: 2024
B4: Revenue | C4: Type | D4: Comps Revenue Multiple | E4: Valuation | F4: Revenue 20% Premium | G4: Revenue 50% Premium | I4: Forbes | J4: 982 | K4: 1548 | L4: 1492 | M4: 1944 | N4: 2183 | P4: 4100 | Q4: 4450 | R4: 5288 | S4: 5370
B5: ='Income Statement'!L7 -> 613.8 | C5: Big Six | D5: 6 | E5: =D5*B5 -> 3682.8 | F5: =E5*0.12 -> 441.936 | G5: =E5*1.5 -> 5524.2 | I5: Sportico | R5: 4710 | S5: 5110
I6: Football Benchmark | S6: 3540
B7: EBITDA Comps
B8: EBITDA | C8: Type | D8: Comps EBITDA Multiple | E8: Valuation | F8: EBITDA 20% Premium | G8: EBITDA 50% Premium
B9: ='Income Statement'!L14 -> 60.6 | C9: Big Six | D9: 34.5 | E9: =B9*D9 -> 2090.7 | F9: =E9*1.2 -> 2508.84 | G9: =E9*1.5 -> 3136.05
B11: DCF
E12: Valuation
E13: 2250
B15: Markham Multivariate Model (MMM)
B16: Revenue + Net Assets | C16: (Net Profit + Revenue) / Revenue | D16: Stadium Utilisation | E16: Wages to Turnover | F16: MMM Valuation
B17: ='Income Statement'!L7+'Balance Sheet'!Q11 -> 808.8 | C17: =('Income Statement'!L31+'Income Statement'!L7)/'Income Statement'!L7 -> 0.92929293 | D17: ='On The Pitch'!J13 -> 0.98702401 | E17: ='Income Statement'!L35 -> 0.62903226 | F17: =(B17*C17*D17)/E17 -> 1179.3659
B21: Valuation Table
B22: Year | C22: Revenue Multiple | D22: EBITDA Multiple | E22: DCF | F22: MMM | G22: Forbes | H22: Football Benchmark | I22: Sportico | K22: Low | L22: High | M22: Avg | N22: AI Recommended
B23: 2024 | C23: =E5 -> 3682.8 | D23: =E9 -> 2090.7 | E23: =$E$13 -> 2250 | F23: =F17 -> 1179.3659 | G23: =S4 -> 5370 | H23: =S6 -> 3540 | I23: =S5 -> 5110 | K23: =MIN(C23:I23) -> 1179.3659 | L23: =MAX(C23:I23) -> 5370 | M23: =AVERAGE(C23:I23) -> 3317.5523
B24: 2023 | C24: =('Income Statement'!K7)*$D$5 -> 3563.4 | D24: =('Income Statement'!K14)*$D$9 -> 2891.1 | E24: =$E$13 -> 2250 | G24: =R4 -> 5288 | M24: =AVERAGE(C24:I24) -> 3498.125
B25: 2022 | C25: =('Income Statement'!J7)*$D$5 -> 3565.8 | D25: =('Income Statement'!J14)*$D$9 -> 3325.8 | E25: =$E$13 -> 2250 | G25: =Q4 -> 4450 | M25: =AVERAGE(C25:I25) -> 3397.9
B26: 2021 | C26: =('Income Statement'!I7)*$D$5 -> 2923.8 | D26: =('Income Statement'!I14)*$D$9 -> 2659.95 | E26: =$E$13 -> 2250 | G26: =P4 -> 4100 | M26: =AVERAGE(C26:I26) -> 2983.4375
B27: 2020 | C27: =('Income Statement'!H7)*$D$5 -> 2939.4 | D27: =('Income Statement'!H14)*$D$9 -> 1438.65 | E27: =$E$13 -> 2250 | G27: =N3 -> 2019 | M27: =AVERAGE(C27:I27) -> 2161.7625
B28: 2019 | C28: =('Income Statement'!G7)*$D$5 -> 3198 | D28: =('Income Statement'!G14)*$D$9 -> 4257.3 | E28: =$E$13 -> 2250 | G28: =N4 -> 2183 | M28: =AVERAGE(C28:I28) -> 2972.075
B29: 2018 | C29: =('Income Statement'!F7)*$D$5 -> 2730.6 | D29: =('Income Statement'!F14)*$D$9 -> 3267.15 | E29: =$E$13 -> 2250 | G29: =M4 -> 1944 | M29: =AVERAGE(C29:I29) -> 2547.9375
B30: 2017 | C30: =('Income Statement'!E7)*$D$5 -> 2187 | D30: =('Income Statement'!E14)*$D$9 -> 2535.75 | E30: =$E$13 -> 2250 | G30: =L4 -> 1492 | M30: =AVERAGE(C30:I30) -> 2116.1875
B31: 2016 | C31: =('Income Statement'!D7)*$D$5 -> 1810.2 | D31: =('Income Statement'!D14)*$D$9 -> 1214.4 | E31: =$E$13 -> 2250 | G31: =K4 -> 1548 | M31: =AVERAGE(C31:I31) -> 1705.65
B32: 2015 | C32: =('Income Statement'!C7)*$D$5 -> 1788 | D32: =('Income Statement'!C14)*$D$9 -> 2518.5 | E32: =$E$13 -> 2250 | G32: =J4 -> 982 | M32: =AVERAGE(C32:I32) -> 1884.625
B34: Key Insights
B35: Insight | C35: Purpose | D35: Type
B36: Valuations Overview | C36: Compare different valuations | D36: 2-D Bar Chart Plotted Horiziontally

Sheet Demographics & Socials
B2: Demographics & Socials
B3: Social Media | I3: Demographics
B4: Liverpool FC | I4: Metric | J4: Result | K4: Description | L4: Source
B5: Platform | C5: Followers | E5: Dates | I5: City / Metro Population | J5: 2240000 | K5: Population of the Liverpool City Region metropolitan area | L5: Wikipedia: “Liverpool City Region”
B6: Facebook | C6: 50 | E6: Engagement | I6: Clubs per City | J6: 2 | K6: Top-flight (Premier League) professional clubs: Liverpool FC & Everton FC | L6: Premier League club list & Wikipedia “Liverpool”
B7: Instagram | C7: 47 | I7: Attendance per Capita | J7: 23 per 1,000 residents | K7: 2023/24 avg home attendance (~52,000) ÷ metro population | L7: Premier League: average attendance; Population above
B8: TikTok | C8: 24.7 | I8: Avg House Price (within 15 mi of Stadium) | J8: 220000 | K8: Mean residential property value in the wider Liverpool region | L8: UK Land Registry / Rightmove
B9: Twitter | C9: 24.7 | I9: Median Hosehold Income | J9: 32000 | K9: Median gross household income in the Liverpool City Region | L9: ONS: Annual Survey of Hours and Earnings
B10: Youtube | C10: 11.3 | I10: Tourist Visits per Year | J10: 63800000 | K10: Total visitor numbers (incl. day-trips) to Liverpool in 2019 | L10: VisitBritain / Liverpool City Council
B11: Total | C11: =SUM(C6:C10) -> 157.7 | I11: GDP per Capita | J11: 23400 | K11: Gross value added per head in the Liverpool City Region | L11: ONS: Regional GDP by Local Enterprise Partnership
I12: Number of Corporate HQs | J12: 0 | K12: No FTSE 100 or Fortune 500 company HQs based in Liverpool; some national HQs (e.g. M & S outlet HQ) | L12: FTSE 100 company HQ listings; Wikipedia
I13: Public Transport Accessibility Score | J13: 68/100 | K13: % of metro population within a 15-minute public transport journey of Anfield | L13: Transport for Liverpool / Citymapper Mobility Index
B14: Posting Activity | I14: Youth Population (U18 %) | J14: 0.21 | K14: Share of residents under 18 years old | L14: ONS mid-year population estimates
B15: Dates | C15: 45778 | D15: 45779 | E15: Etc | I15: Digital Penetration | J15: 0.98 | K15: % of households with fixed broadband or smartphone access in the Liverpool City Region | L15: Ofcom Connected Nations report
B16: Facebook | C16: 2 | D16: 0
B17: Instagram | C17: 1 | D17: 2
B18: TikTok | C18: 2 | D18: 4
B19: Twitter | C19: 0 | D19: 1
B20: Youtube | C20: 0 | D20: 10
B21: Weibo | C21: 3 | D21: 0
B24: Key Insights
B25: Name | C25: Data #1 | D25: Data #2 | E25: Purpose | F25: Chart Type
B26: Followers by Platform | C26: Platform | D26: Followers | E26: Compare LFC's reach across platforms | F26: Pie Chart
B27: Followers over time | C27: Total Followers | D27: Months | E27: Show development of total followers | F27: Line Chart
B28: Engagement per Post VS Months | C28: [Total engagemnets] / [Total posts] / [Followers] | D28: Months | E28: Show how engagemnt maps across time. | F28: Line Chart
B29: Attendance per Capita | C29: Avg Attendance | D29: Metro Population | E29: Reveal how intensely the local population supports home matches | F29: Gauge chart or bar chart

Sheet Cash Flow Statement (Work On)
B2: Cash Flow Statement
B3: Liverpool FC | C3: 2015 | D3: 2016 | E3: 2017 | F3: 2018 | G3: 2019 | H3: 2020 | I3: 2021 | J3: 2022 | K3: 2023 | L3: 2024
B4: Cash Flow From Operations
B5: Operating Profit / (Loss) | C5: ='Income Statement'!C21 -> 8.9 | D5: ='Income Statement'!D21 -> -42.5 | E5: ='Income Statement'!E21 -> 6.6 | F5: ='Income Statement'!F21 -> 7.1 | G5: ='Income Statement'!G21 -> 0.5 | H5: ='Income Statement'!H21 -> -74.3 | I5: ='Income Statement'!I21 -> -40.3 | J5: ='Income Statement'!J21 -> -17.9 | ... L5: ='Income Statement'!L21 -> -69.7
B6: Depreciation, Amortization & Impairement | C6: =ABS('Income Statement'!C20) -> 64.1 | D6: =ABS('Income Statement'!D20) -> 77.7 | E6: =ABS('Income Statement'!E20) -> 66.9 | F6: =ABS('Income Statement'!F20) -> 87.6 | G6: =ABS('Income Statement'!G20) -> 122.9 | H6: =ABS('Income Statement'!H20) -> 116 | I6: =ABS('Income Statement'!I20) -> 117.4 | J6: =ABS('Income Statement'!J20) -> 114.3 | ... L6: =ABS('Income Statement'!L20) -> 130.3
B7: Profit on disposal of registrations | C7: 0 | D7: ='Income Statement'!D23 -> 42.1 | E7: ='Income Statement'!E23 -> 38.3 | F7: ='Income Statement'!F23 -> 123.9 | G7: ='Income Statement'!G23 -> 45.2 | H7: ='Income Statement'!H23 -> 26.9 | I7: ='Income Statement'!I23 -> 39.3 | J7: ='Income Statement'!J23 -> 28.1 | K7: ='Income Statement'!K23 -> 33.8 | L7: ='Income Statement'!L23 -> 22
B8: Adjusted EBITDA | C8: =C5+C6-C7 -> 73 | D8: =D5+D6-D7 -> -6.9 | E8: =E5+E6-E7 -> 35.2 | F8: =F5+F6-F7 -> -29.2 | G8: =G5+G6-G7 -> 78.2 | H8: =H5+H6-H7 -> 14.8 | I8: =I5+I6-I7 -> 37.8 | J8: =J5+J6-J7 -> 68.3 | ... L8: =L5+L6-L7 -> 38.6
B9: Exceptional Cash Expenses | C9: ='Income Statement'!C22 -> 0.3 | D9: ='Income Statement'!D22 -> -15.7 | E9: ='Income Statement'!E22 -> 0 | F9: ='Income Statement'!F22 -> 0 | G9: ='Income Statement'!G22 -> 0 | H9: ='Income Statement'!H22 -> 0 | I9: ='Income Statement'!I22 -> 0 | J9: ='Income Statement'!J22 -> 0 | ... L9: ='Income Statement'!L22 -> 0
B10: CFO before △ in working capital | C10: =C8-C9 -> 72.7 | D10: =D8-D9 -> 8.8 | E10: =E8+E9 -> 35.2 | F10: =F8+F9 -> -29.2 | G10: =G8+G9 -> 78.2 | H10: =H8+H9 -> 14.8 | I10: =I8+I9 -> 37.8 | J10: =J8+J9 -> 68.3 | K10: =K8+K9 -> 50 | L10: =L8+L9 -> 38.6
B11: Change in Working Capital | C11: -7.62 | D11: 12.7 | G11: 7.4 | H11: 52.1 | I11: -54 | J11: 16.3 | K11: 5.1 | L11: 22.6
B12: CFO before Interest and Tax | C12: =C10+C11 -> 65.08 | D12: =D10+D11 -> 21.5 | E12: =E10+E11 -> 35.2 | F12: =F10+F11 -> -29.2 | G12: =G10+G11 -> 85.6 | H12: =H10+H11 -> 66.9 | I12: =I10+I11 -> -16.2 | J12: =J10+J11 -> 84.6 | ... L12: =L10+L11 -> 61.2
B13: Net Cash Interest Payments | C13: -2.8 | D13: -2.3 | E13: -2.5 | F13: -1.8 | G13: -1.8 | H13: -1.8 | I13: -3.3 | J13: -2.2 | K13: -4.1 | L13: -8.3
B14: Tax Payments | C14: 0 | D14: 0 | E14: 0 | F14: 0 | G14: 0 | H14: 0 | I14: 0 | J14: 0 | K14: 0 | L14: 0
B15: Cash Flow from Operations | C15: =C12+C13+C14 -> 62.28 | D15: =D12+D13+D14 -> 19.2 | E15: =E12+E13+E14 -> 32.7 | F15: =F12+F13+F14 -> -31 | G15: =G12+G13+G14 -> 83.8 | H15: =H12+H13+H14 -> 65.1 | I15: =I12+I13+I14 -> -19.5 | J15: =J12+J13+J14 -> 82.4 | ... L15: =L12+L13+L14 -> 52.9
B17: Cash Flow From Investing
B18: Player sales | C18: 36.9 | D18: 62 | E18: 58.4 | F18: 104.9 | G18: 114.8 | H18: 32 | I18: 34.5 | J18: 32.2 | K18: 39.1 | L18: 49.1
B19: Players Purchases | C19: -95.6 | D19: -99.8 | E19: -97.2 | F19: -154.1 | G19: -173.9 | H19: -121.5 | I19: -90.2 | J19: -97.2 | K19: -122.2 | L19: -181.6
B20: Net Player Trading | C20: =C18+C19 -> -58.7 | D20: =D18+D19 -> -37.8 | E20: =E18+E19 -> -38.8 | F20: =F18+F19 -> -49.2 | G20: =G18+G19 -> -59.1 | H20: =H18+H19 -> -89.5 | I20: =I18+I19 -> -55.7 | J20: =J18+J19 -> -65 | ... L20: =L18+L19 -> -132.5
B21: Capex | C21: -39.6 | D21: -57.4 | E21: -52 | F21: -15.9 | G21: -22.6 | H21: -29.7 | I21: -11.35 | J21: -23.4 | K21: -49.8 | L21: -56
B22: Cash Flow from Investing | C22: =C18+C19+C21 -> -98.3 | D22: =D18+D19+D21 -> -95.2 | E22: =E18+E19+E21 -> -90.8 | F22: =F18+F19+F21 -> -65.1 | G22: =G18+G19+G21 -> -81.7 | H22: =H18+H19+H21 -> -119.2 | I22: =I18+I19+I21 -> -67.05 | J22: =J18+J19+J21 -> -88.4 | ... L22: =L18+L19+L21 -> -188.5
B23: Cash Flow before Financing | C23: =C15+C22 -> -36.02 | D23: =D15+D22 -> -76 | E23: =E15+E22 -> -58.1 | F23: =F15+F22 -> -96.1 | G23: =G15+G22 -> 2.1 | H23: =H15+H22 -> -54.1 | I23: =I15+I22 -> -86.55 | J23: =J15+J22 -> -6 | ... L23: =L15+L22 -> -135.6
B25: Cash Flow from Financing
B26: Owner Loans | C26: 49 | D26: 59.6 | E26: -2.4 | F26: -12.9 | G26: -14 | H26: -7.9 | I26: 0 | J26: 0 | K26: 0 | L26: 127.3
B27: Share Capital | C27: 0 | D27: 0 | E27: 0 | F27: 0 | G27: 0 | H27: 0 | I27: 0 | J27: 0 | K27: 0 | L27: 0
B28: Dividends | C28: 0 | D28: 0 | E28: 0 | F28: 0 | G28: 0 | H28: 0 | I28: 0 | J28: 0 | K28: 0 | L28: 0
B29: Owner Financing | C29: =SUM(C26:C28) -> 49 | D29: =SUM(D26:D28) -> 59.6 | E29: =SUM(E26:E28) -> -2.4 | F29: =SUM(F26:F28) -> -12.9 | G29: =SUM(G26:G28) -> -14 | H29: =SUM(H26:H28) -> -7.9 | I29: =SUM(I26:I28) -> 0 | J29: =SUM(J26:J28) -> 0 | ... L29: =SUM(L26:L28) -> 127.3
B30: Net Bank Loans (Repayments) | C30: -9 | D30: 3 | E30: 18 | F30: -17 | G30: -6 | H30: 146.9 | I30: -70.4 | J30: -40 | K30: 38 | L30: -10.2
B31: Cash Flow from Financing | C31: =C29+C30 -> 40 | D31: =D29+D30 -> 62.6 | E31: =E29+E30 -> 15.6 | F31: =F29+F30 -> -29.9 | G31: =G29+G30 -> -20 | H31: =H29+H30 -> 139 | I31: =I29+I30 -> -70.4 | J31: =J29+J30 -> -40 | ... L31: =L29+L30 -> 117.1
B33: Net Cash Flow | C33: =C15+C22+C31 -> 3.98 | D33: =D15+D22+D31 -> -13.4 | E33: =E15+E22+E31 -> -42.5 | F33: =F15+F22+F31 -> -126 | G33: =G15+G22+G31 -> -17.9 | H33: =H15+H22+H31 -> 84.9 | I33: =I15+I22+I31 -> -156.95 | J33: =J15+J22+J31 -> -46 | ... L33: =L15+L22+L31 -> -18.5
B34: Cash: Start of Year | D34: =C35 -> 3.98 | E34: =D35 -> -9.42 | F34: =E35 -> -51.92 | G34: =F35 -> -177.92 | H34: =G35 -> -195.82 | I34: =H35 -> -110.92 | J34: =I35 -> -267.87 | K34: =J35 -> -313.87 | L34: =K35 -> -357.77
B35: Cash: End of Year | C35: =C34+C33 -> 3.98 | D35: =D34+D33 -> -9.42 | E35: =E34+E33 -> -51.92 | F35: =F34+F33 -> -177.92 | G35: =G34+G33 -> -195.82 | H35: =H34+H33 -> -110.92 | I35: =I34+I33 -> -267.87 | J35: =J34+J33 -> -313.87 | ... L35: =L34+L33 -> -376.27
